Traceback (most recent call last):
  File "/usr/local/lib/python3.10/site-packages/huggingface_hub/utils/_errors.py", line 304, in hf_raise_for_status
    response.raise_for_status()
  File "/usr/local/lib/python3.10/site-packages/requests/models.py", line 1024, in raise_for_status
    raise HTTPError(http_error_msg, response=self)
requests.exceptions.HTTPError: 403 Client Error: Forbidden for url: https://huggingface.co/meta-llama/Meta-Llama-3.1-8B-Instruct/resolve/main/config.json

The above exception was the direct cause of the following exception:

Traceback (most recent call last):
  File "/usr/local/lib/python3.10/site-packages/transformers/utils/hub.py", line 402, in cached_file
    resolved_file = hf_hub_download(
  File "/usr/local/lib/python3.10/site-packages/huggingface_hub/utils/_deprecation.py", line 101, in inner_f
    return f(*args, **kwargs)
  File "/usr/local/lib/python3.10/site-packages/huggingface_hub/utils/_validators.py", line 114, in _inner_fn
    return fn(*args, **kwargs)
  File "/usr/local/lib/python3.10/site-packages/huggingface_hub/file_download.py", line 1240, in hf_hub_download
    return _hf_hub_download_to_cache_dir(
  File "/usr/local/lib/python3.10/site-packages/huggingface_hub/file_download.py", line 1347, in _hf_hub_download_to_cache_dir
    _raise_on_head_call_error(head_call_error, force_download, local_files_only)
  File "/usr/local/lib/python3.10/site-packages/huggingface_hub/file_download.py", line 1854, in _raise_on_head_call_error
    raise head_call_error
  File "/usr/local/lib/python3.10/site-packages/huggingface_hub/file_download.py", line 1751, in _get_metadata_or_catch_error
    metadata = get_hf_file_metadata(
  File "/usr/local/lib/python3.10/site-packages/huggingface_hub/utils/_validators.py", line 114, in _inner_fn
    return fn(*args, **kwargs)
  File "/usr/local/lib/python3.10/site-packages/huggingface_hub/file_download.py", line 1673, in get_hf_file_metadata
    r = _request_wrapper(
  File "/usr/local/lib/python3.10/site-packages/huggingface_hub/file_download.py", line 376, in _request_wrapper
    response = _request_wrapper(
  File "/usr/local/lib/python3.10/site-packages/huggingface_hub/file_download.py", line 400, in _request_wrapper
    hf_raise_for_status(response)
  File "/usr/local/lib/python3.10/site-packages/huggingface_hub/utils/_errors.py", line 321, in hf_raise_for_status
    raise GatedRepoError(message, response) from e
huggingface_hub.utils._errors.GatedRepoError: 403 Client Error. (Request ID: Root=1-66ec78f5-5033d0c50e6f6a7d70ce8eb7;2cca8083-b4ea-456c-ad16-8ee78f77e88a)

Cannot access gated repo for url https://huggingface.co/meta-llama/Meta-Llama-3.1-8B-Instruct/resolve/main/config.json.
Access to model meta-llama/Meta-Llama-3.1-8B-Instruct is restricted and you are not in the authorized list. Visit https://huggingface.co/meta-llama/Meta-Llama-3.1-8B-Instruct to ask for access.

The above exception was the direct cause of the following exception:

Traceback (most recent call last):
  File "/app/automodel_final.py", line 325, in <module>
    engine = TranslatorEngine(dataset, split, output, batch_size, sample_limit, continuous)
  File "/app/automodel_final.py", line 83, in __init__
    self.model = AutoModelForCausalLM.from_pretrained(
  File "/usr/local/lib/python3.10/site-packages/transformers/models/auto/auto_factory.py", line 524, in from_pretrained
    config, kwargs = AutoConfig.from_pretrained(
  File "/usr/local/lib/python3.10/site-packages/transformers/models/auto/configuration_auto.py", line 976, in from_pretrained
    config_dict, unused_kwargs = PretrainedConfig.get_config_dict(pretrained_model_name_or_path, **kwargs)
  File "/usr/local/lib/python3.10/site-packages/transformers/configuration_utils.py", line 632, in get_config_dict
    config_dict, kwargs = cls._get_config_dict(pretrained_model_name_or_path, **kwargs)
  File "/usr/local/lib/python3.10/site-packages/transformers/configuration_utils.py", line 689, in _get_config_dict
    resolved_config_file = cached_file(
  File "/usr/local/lib/python3.10/site-packages/transformers/utils/hub.py", line 420, in cached_file
    raise EnvironmentError(
OSError: You are trying to access a gated repo.
Make sure to have access to it at https://huggingface.co/meta-llama/Meta-Llama-3.1-8B-Instruct.
403 Client Error. (Request ID: Root=1-66ec78f5-5033d0c50e6f6a7d70ce8eb7;2cca8083-b4ea-456c-ad16-8ee78f77e88a)

Cannot access gated repo for url https://huggingface.co/meta-llama/Meta-Llama-3.1-8B-Instruct/resolve/main/config.json.
Access to model meta-llama/Meta-Llama-3.1-8B-Instruct is restricted and you are not in the authorized list. Visit https://huggingface.co/meta-llama/Meta-Llama-3.1-8B-Instruct to ask for access.
